<mujoco model="humanoid">

    <compiler angle="degree" inertiafromgeom="true" />
    
    <default>
        <joint armature="1" damping="1" limited="true" />
        <geom conaffinity="0" condim="1" contype="0" material="geom" />
        <motor ctrllimited="true" ctrlrange="-.4 .4" />
    </default>

    <option iterations="8" timestep="0.003" />
    
    <custom>
        <numeric data="2500" name="constraint_limit_stiffness" />
        <numeric data="27000" name="constraint_stiffness" />
        <numeric data="30" name="constraint_ang_damping" />
        <numeric data="80" name="constraint_vel_damping" />
        <numeric data="-0.05" name="ang_damping" />
        <numeric data="0.5" name="joint_scale_pos" />
        <numeric data="0.1" name="joint_scale_ang" />
        <numeric data="0" name="spring_mass_scale" />
        <numeric data="1" name="spring_inertia_scale" />
        <numeric data="20" name="matrix_inv_iterations" />
        <numeric data="15" name="solver_maxls" />
    </custom>
    
    <size nkey="5" nuser_geom="1" />
    
    <visual>
        <map fogend="5" fogstart="3" />
    </visual>
    
    <asset>
        <texture builtin="gradient" height="100" rgb1=".4 .5 .6" rgb2="0 0 0" type="skybox" width="100" />
        <texture builtin="flat" height="1278" mark="cross" markrgb="1 1 1" name="texgeom" random="0.01" rgb1="0.8 0.6 0.4" rgb2="0.8 0.6 0.4" type="cube" width="127" />
        <texture builtin="checker" height="100" name="texplane" rgb1="0 0 0" rgb2="0.8 0.8 0.8" type="2d" width="100" />
        <material name="MatPlane" reflectance="0.5" shininess="1" specular="1" texrepeat="60 60" texture="texplane" />
        <material name="geom" texture="texgeom" texuniform="true" />
    </asset>
    
    <worldbody>
        <light cutoff="100" diffuse="1 1 1" dir="-0 0 -1.3" directional="true" exponent="1" pos="0 0 1.3" specular=".1 .1 .1" />
        <geom conaffinity="1" condim="3" friction="1 .1 .1" material="MatPlane" name="floor" pos="0 0 0.0" size="20 20 0.125" type="plane" />

        <body name="alfredo" pos="2.0 0 0.87562">
            <camera name="followme" mode="trackcom" pos="0 -4 0" xyaxes="1 0 0 0 0 1" />

            <joint armature="0" damping="0" limited="false" name="r" pos="0 0 0" stiffness="0" type="free" />
            <geom fromto="0 0 -.118 0 0 .118" name="t1" size="0.2585" type="box" />
            <geom name="h" pos="0 0 .29" size=".2" type="sphere" user="258" />

            <body name="upper_arm_r" pos="0.018568 -0.413263 0.068">
                <joint armature="0.0068" axis="2 1 1" name="shoulder_1_r" pos="0 0 0" range="-85 60" stiffness="1" type="hinge" />
                <joint armature="0.0051" axis="0 -1 1" name="shoulder_2_r" pos="0 0 0" range="-85 60" stiffness="1" type="hinge" />
                <geom fromto="0 -.13788 0 0 .13788 0" name="triceps_r" size="0.087812" type="box" />

                <body name="lower_arm_r" pos="0 -0.293311 0"> 
                    <joint armature="0.0028" axis="0 -1 1" name="elbow_r" pos="0 0 0" range="-90 50" stiffness="0" type="hinge" />
                    <geom fromto="0 -.1167525 0 0 .1167525 0" name="forearm_r" size="0.087738" type="box" />
                    <geom contype="1" pos="0 -0.2011965 0" name="gripper_r" size="0.084444" type="sphere" />
                </body>
            </body>

            <body name="upper_arm_l" pos="0.018568 0.413263 0.068">
                <joint armature="0.0068" axis="2 -1 1" name="shoulder_1_l" pos="0 0 0" range="-85 60" stiffness="1" type="hinge" />
                <joint armature="0.0051" axis="0 1 1" name="shoulder_2_l" pos="0 0 0" range="-85 60" stiffness="1" type="hinge" />
                <geom fromto="0 -.13788 0 0 .13788 0" name="triceps_l" size="0.087812" type="box" />

                <body name="lower_arm_l" pos="0 0.293311 0"> 
                    <joint armature="0.0028" axis="0 -1 -1" name="elbow_l" pos="0 0 0" range="-90 50" stiffness="0" type="hinge" />
                    <geom fromto="0 -.1167525 0 0 .1167525 0" name="forearm_l" size="0.087738" type="box" />
                    <geom contype="1" pos="0 0.2011965 0" name="gripper_l" size="0.084444" type="sphere" />
                </body>
            </body>

            <body name="lw" pos="0 0 -.2159" quat="1.000 0 -0.002 0">
                <joint armature="0.02" axis="0 1 0" damping="5" name="ab_y" pos="0 0 0" range="-75 30" stiffness="10" type="hinge" />
                <joint armature="0.02" axis="0 0 1" damping="5" name="ab_z" pos="0 0 0" range="-45 45" stiffness="20" type="hinge" />
                <geom fromto="0 0 -.0765 0 0 .0765" name="t2" size="0.2175" type="box" />

                <body name="pelv" pos="0 0 -.146907" quat="1.000 0 -0.002 0">
                    <joint armature="0.02" axis="1 0 0" damping="5" name="ab_x" pos="0 0 0" range="-35 35" stiffness="10" type="hinge" />
                    <geom fromto="0 0 -.04995 0 0 .04995" name="booty" size="0.2445" type="box" />

                    <body name="thigh_r" pos="0 -0.138628 -0.1654815">
                        <joint armature="0.01" axis="1 0 0" damping="5" name="hip_r_x" pos="0 0 0" range="-25 5" stiffness="10" type="hinge" />
                        <joint armature="0.0080" axis="0 1 0" damping="5" name="hip_r_y" pos="0 0 0" range="-110 20" stiffness="10" type="hinge" />
                        <joint armature="0.01" axis="0 0 1" damping="5" name="hip_r_z" pos="0 0 0" range="-60 35" stiffness="10" type="hinge" />
                        <geom fromto="0 0 -.105 0 0 .105" name="quad_r" size="0.0804" type="box" />

                        <body name="shin_r" pos="0 0 -.1948355">
                            <joint armature="0.006" axis="0 -1 0" name="knee_r" pos="0 0 0" range="-160 -2" type="hinge" />
                            <geom fromto="0 0 -.063994 0 0 .063994" name="calves_r" size="0.0816535" type="box" />
                            
                            <body name="foot_r" pos="0 0 -0.0884431">
                                <joint armature="0.006" axis="0 -1 0" name="ankle_r" pos="0 0 0" range="-45 20" type="hinge" />
                                <!-- geom contype="1" fromto="0 0 -.0022983 0 0 .0022983" name="footm_r" size="0.128965" type="cylinder" /-->
                                <geom contype="1" fromto="-0.10 0 0 0.178 0 0" name="footm_r" size="0.042983" type="box"/>
                            </body>
                        </body>
                    </body>
                    
                    <body name="thigh_l" pos="0 0.138628 -0.1654815">
                        <joint armature="0.01" axis="-1 0 0" damping="5" name="hip_l_x" pos="0 0 0" range="-25 5" stiffness="10" type="hinge" />
                        <joint armature="0.0080" axis="0 1 0" damping="5" name="hip_l_y" pos="0 0 0" range="-110 20" stiffness="10" type="hinge" />
                        <joint armature="0.01" axis="0 0 -1" damping="5" name="hip_l_z" pos="0 0 0" range="-60 35" stiffness="10" type="hinge" />
                        <geom fromto="0 0 -.105 0 0 .105" name="quad_l" size="0.0804" type="box" />

                        <body name="shin_l" pos="0 0 -.1948355">
                            <joint armature="0.006" axis="0 -1 0" name="knee_l" pos="0 0 0" range="-160 -2" type="hinge" />
                            <geom fromto="0 0 -.063994 0 0 .063994" name="calves_l" size="0.0816535" type="box" />
                            
                            <body name="foot_l" pos="0 0 -0.0884431">
                                <joint armature="0.006" axis="0 -1 0" name="ankle_l" pos="0 0 0" range="-45 20" type="hinge" />
                                <!-- geom contype="1" fromto="0 0 -.0022983 0 0 .0022983" name="footm_l" size="0.128965" type="cylinder" /-->
                                <geom contype="1" fromto="-0.10 0 0 0.178 0 0" name="footm_l" size="0.042983" type="box"/>
                            </body>
                        </body>
                    </body>
                </body>
            </body>
        </body>

        <!-- Target -->
        <body name="target" pos="0 0 1.0">
			<!-- The joint `ref` attributes are removed for brax. -->
            <joint armature="0" axis="1 0 0" damping="0" limited="true" name="target_x" pos="0 0 0" range="-100.0 100.0" stiffness="0" type="slide"/>
            <joint armature="0" axis="0 1 0" damping="0" limited="true" name="target_y" pos="0 0 0" range="-100.0 100.0" stiffness="0" type="slide"/>
			<geom conaffinity="0" contype="0" name="target" pos="0 0 0" size=".1" type="sphere"/>
		</body>

    </worldbody>

    <actuator>
        <motor gear="100" joint="ab_y" name="ab_y" />
        <motor gear="100" joint="ab_z" name="ab_z" />
        <motor gear="100" joint="ab_x" name="ab_x" />
        <motor gear="100" joint="hip_r_x" name="hip_r_x" />
        <motor gear="100" joint="hip_r_z" name="hip_r_z" />
        <motor gear="300" joint="hip_r_y" name="hip_r_y" />
        <motor gear="200" joint="knee_r" name="knee_r" />
        <motor gear="200" joint="ankle_r" name="ankle_r" />
        <motor gear="100" joint="hip_l_x" name="hip_l_x" />
        <motor gear="100" joint="hip_l_z" name="hip_l_z" />
        <motor gear="300" joint="hip_l_y" name="hip_l_y" />
        <motor gear="200" joint="knee_l" name="knee_l" />
        <motor gear="200" joint="ankle_l" name="ankle_l" />
        <motor gear="25" joint="shoulder_1_r" name="shoulder_1_r" />
        <motor gear="25" joint="shoulder_2_r" name="shoulder_2_r" />
        <motor gear="25" joint="elbow_r" name="elbow_r" />
        <motor gear="25" joint="shoulder_1_l" name="shoulder_1_l" />
        <motor gear="25" joint="shoulder_2_l" name="shoulder_2_l" />
        <motor gear="25" joint="elbow_l" name="elbow_l" />
    </actuator>

</mujoco>
